<robot name="mirror666">
  <link name="world"/>
  <joint type="floating" name="floating_base">
    <parent link="world"/>
    <child link="base_link"/>
  </joint>
  <link name="base_link">
    <inertial>
      <inertia ixz="0.0" ixx="0.7999648" ixy="0.0" izz="1.3999648" iyy="1.0" iyz="0.0"/>
      <mass value="15.0"/>
    </inertial>
    <visual>
      <geometry>
        <mesh filename="package://esa_mirror/model_resources/meshes/base.stl" scale="0.008 0.008 0.008"/>
      </geometry>
      <material name="gray">
        <color rgba="0.5 0.5 0.5 1.0"/>
      </material>
      <origin xyz="0 -0.052 -0.2" rpy="0 0 1.57079632679"/>
    </visual>
    <collision>
      <geometry>
        <mesh filename="package://esa_mirror/model_resources/meshes/base.stl" scale="0.008 0.008 0.008"/>
      </geometry>
      <origin xyz="0 -0.052 -0.2" rpy="0 0 1.57079632679"/>
    </collision>
  </link>
  <joint type="fixed" name="A1_base_connection">
    <parent link="base_link"/>
    <child link="A1_base"/>
    <origin xyz="0.2999824 -0.1732 0.0" rpy="3.14159265359 0.0 0.0"/>
  </joint>
  <link name="A1_base"/>
  <link name="A1_link">
    <inertial>
      <inertia ixz="0.0" ixx="0.043675" ixy="0.0" izz="0.00735" iyy="0.043675" iyz="0.0"/>
      <mass value="3.0"/>
      <origin xyz="0.0 0.0 0.2" rpy="0.0 0.0 0.0"/>
    </inertial>
    <visual>
      <geometry>
        <cylinder length="0.4" radius="0.07"/>
      </geometry>
      <material name="blue">
        <color rgba="0.0 0.0 1.0 1.0"/>
      </material>
      <origin xyz="0.0 0.0 0.2" rpy="0.0 0.0 0.0"/>
    </visual>
    <collision>
      <geometry>
        <cylinder length="0.4" radius="0.07"/>
      </geometry>
      <origin xyz="0.0 0.0 0.2" rpy="0.0 0.0 0.0"/>
    </collision>
  </link>
  <joint type="revolute" name="A1_joint">
    <parent link="A1_base"/>
    <child link="A1_link"/>
    <origin xyz="0 0 0" rpy="0 0 0"/>
    <axis xyz="0 0 1" rpy="0.0 0.0 0.0"/>
    <limit velocity="12" effort="200" lower="-6.283" upper="6.283"/>
  </joint>
  <link name="A2_link">
    <inertial>
      <inertia ixz="0.0" ixx="0.0049" ixy="0.0" izz="0.0049" iyy="0.0049" iyz="0.0"/>
      <mass value="1.5"/>
      <origin xyz="0 0 0.07" rpy="0 0 0"/>
    </inertial>
    <visual>
      <geometry>
        <mesh filename="package://esa_mirror/model_resources/meshes/simple/esa_elbow_base.stl" scale="0.001 0.001 0.001"/>
      </geometry>
      <material name="custom"/>
      <origin xyz="0 0 0" rpy="0 0 0"/>
    </visual>
    <collision>
      <geometry>
        <mesh filename="package://esa_mirror/model_resources/meshes/simple/esa_elbow_base.stl" scale="0.001 0.001 0.001"/>
      </geometry>
      <origin xyz="0 0 0" rpy="0 0 0"/>
    </collision>
  </link>
  <joint type="fixed" name="A2_joint">
    <parent link="A1_link"/>
    <child link="A2_link"/>
    <origin xyz="0 0 0.4" rpy="0 0 0"/>
  </joint>
  <link name="A3_link">
    <inertial>
      <inertia ixz="0.0" ixx="0.0049" ixy="0.0" izz="0.0049" iyy="0.0049" iyz="0.0"/>
      <mass value="1.5"/>
      <origin xyz="0 -0.075 0" rpy="0 0 0"/>
    </inertial>
    <visual>
      <geometry>
        <mesh filename="package://esa_mirror/model_resources/meshes/simple/esa_elbow_link.stl" scale="0.001 0.001 0.001"/>
      </geometry>
      <material name="custom"/>
      <origin xyz="0 0 0" rpy="0 0 0"/>
    </visual>
    <collision>
      <geometry>
        <mesh filename="package://esa_mirror/model_resources/meshes/simple/esa_elbow_link.stl" scale="0.001 0.001 0.001"/>
      </geometry>
      <origin xyz="0 0 0" rpy="0 0 0"/>
    </collision>
  </link>
  <joint type="revolute" name="A3_joint">
    <parent link="A2_link"/>
    <child link="A3_link"/>
    <origin xyz="0 -0.075 0.07" rpy="0 0 0"/>
    <axis xyz="0 1 0" rpy="0.0 0.0 0.0"/>
    <limit velocity="12" effort="200" lower="-3.1415" upper="3.1415"/>
  </joint>
  <link name="A4_link">
    <inertial>
      <inertia ixz="0.0" ixx="0.043675" ixy="0.0" izz="0.00735" iyy="0.043675" iyz="0.0"/>
      <mass value="3.0"/>
      <origin xyz="0.0 0.0 0.2" rpy="0.0 0.0 0.0"/>
    </inertial>
    <visual>
      <geometry>
        <cylinder length="0.4" radius="0.07"/>
      </geometry>
      <material name="blue">
        <color rgba="0.0 0.0 1.0 1.0"/>
      </material>
      <origin xyz="0.0 0.0 0.2" rpy="0.0 0.0 0.0"/>
    </visual>
    <collision>
      <geometry>
        <cylinder length="0.4" radius="0.07"/>
      </geometry>
      <origin xyz="0.0 0.0 0.2" rpy="0.0 0.0 0.0"/>
    </collision>
  </link>
  <joint type="fixed" name="A4_joint">
    <parent link="A3_link"/>
    <child link="A4_link"/>
    <origin xyz="0 -0.075 0.07" rpy="0 0 0"/>
  </joint>
  <link name="A5_link">
    <inertial>
      <inertia ixz="0.0" ixx="0.0049" ixy="0.0" izz="0.0049" iyy="0.0049" iyz="0.0"/>
      <mass value="1.5"/>
      <origin xyz="0 0 0.07" rpy="0 0 0"/>
    </inertial>
    <visual>
      <geometry>
        <mesh filename="package://esa_mirror/model_resources/meshes/simple/esa_elbow_base.stl" scale="0.001 0.001 0.001"/>
      </geometry>
      <material name="custom"/>
      <origin xyz="0 0 0" rpy="0 0 0"/>
    </visual>
    <collision>
      <geometry>
        <mesh filename="package://esa_mirror/model_resources/meshes/simple/esa_elbow_base.stl" scale="0.001 0.001 0.001"/>
      </geometry>
      <origin xyz="0 0 0" rpy="0 0 0"/>
    </collision>
  </link>
  <joint type="fixed" name="A5_joint">
    <parent link="A4_link"/>
    <child link="A5_link"/>
    <origin xyz="0 0 0.4" rpy="0 0 3.14159265359"/>
  </joint>
  <link name="A6_link">
    <inertial>
      <inertia ixz="0.0" ixx="0.0049" ixy="0.0" izz="0.0049" iyy="0.0049" iyz="0.0"/>
      <mass value="1.5"/>
      <origin xyz="0 -0.075 0" rpy="0 0 0"/>
    </inertial>
    <visual>
      <geometry>
        <mesh filename="package://esa_mirror/model_resources/meshes/simple/esa_elbow_link.stl" scale="0.001 0.001 0.001"/>
      </geometry>
      <material name="custom"/>
      <origin xyz="0 0 0" rpy="0 0 0"/>
    </visual>
    <collision>
      <geometry>
        <mesh filename="package://esa_mirror/model_resources/meshes/simple/esa_elbow_link.stl" scale="0.001 0.001 0.001"/>
      </geometry>
      <origin xyz="0 0 0" rpy="0 0 0"/>
    </collision>
  </link>
  <joint type="revolute" name="A6_joint">
    <parent link="A5_link"/>
    <child link="A6_link"/>
    <origin xyz="0 -0.075 0.07" rpy="0 0 0"/>
    <axis xyz="0 1 0" rpy="0.0 0.0 0.0"/>
    <limit velocity="12" effort="200" lower="-3.1415" upper="3.1415"/>
  </joint>
  <link name="A7_link">
    <inertial>
      <inertia ixz="0.0" ixx="0.043675" ixy="0.0" izz="0.00735" iyy="0.043675" iyz="0.0"/>
      <mass value="3.0"/>
      <origin xyz="0.0 0.0 0.2" rpy="0.0 0.0 0.0"/>
    </inertial>
    <visual>
      <geometry>
        <cylinder length="0.4" radius="0.07"/>
      </geometry>
      <material name="blue">
        <color rgba="0.0 0.0 1.0 1.0"/>
      </material>
      <origin xyz="0.0 0.0 0.2" rpy="0.0 0.0 0.0"/>
    </visual>
    <collision>
      <geometry>
        <cylinder length="0.4" radius="0.07"/>
      </geometry>
      <origin xyz="0.0 0.0 0.2" rpy="0.0 0.0 0.0"/>
    </collision>
  </link>
  <joint type="revolute" name="A7_joint">
    <parent link="A6_link"/>
    <child link="A7_link"/>
    <origin xyz="0 -0.075 0.07" rpy="0 0 0"/>
    <axis xyz="0 0 1" rpy="0.0 0.0 0.0"/>
    <limit velocity="12" effort="200" lower="-6.283" upper="6.283"/>
  </joint>
  <link name="A8_link">
    <inertial>
      <inertia ixz="0.0" ixx="0.0049" ixy="0.0" izz="0.0049" iyy="0.0049" iyz="0.0"/>
      <mass value="1.5"/>
      <origin xyz="0 0 0.07" rpy="0 0 0"/>
    </inertial>
    <visual>
      <geometry>
        <mesh filename="package://esa_mirror/model_resources/meshes/simple/esa_elbow_base.stl" scale="0.001 0.001 0.001"/>
      </geometry>
      <material name="custom"/>
      <origin xyz="0 0 0" rpy="0 0 0"/>
    </visual>
    <collision>
      <geometry>
        <mesh filename="package://esa_mirror/model_resources/meshes/simple/esa_elbow_base.stl" scale="0.001 0.001 0.001"/>
      </geometry>
      <origin xyz="0 0 0" rpy="0 0 0"/>
    </collision>
  </link>
  <joint type="fixed" name="A8_joint">
    <parent link="A7_link"/>
    <child link="A8_link"/>
    <origin xyz="0 0 0.4" rpy="0 0 0"/>
  </joint>
  <link name="A9_link">
    <inertial>
      <inertia ixz="0.0" ixx="0.0049" ixy="0.0" izz="0.0049" iyy="0.0049" iyz="0.0"/>
      <mass value="1.5"/>
      <origin xyz="0 -0.075 0" rpy="0 0 0"/>
    </inertial>
    <visual>
      <geometry>
        <mesh filename="package://esa_mirror/model_resources/meshes/simple/esa_elbow_link.stl" scale="0.001 0.001 0.001"/>
      </geometry>
      <material name="custom"/>
      <origin xyz="0 0 0" rpy="0 0 0"/>
    </visual>
    <collision>
      <geometry>
        <mesh filename="package://esa_mirror/model_resources/meshes/simple/esa_elbow_link.stl" scale="0.001 0.001 0.001"/>
      </geometry>
      <origin xyz="0 0 0" rpy="0 0 0"/>
    </collision>
  </link>
  <joint type="revolute" name="A9_joint">
    <parent link="A8_link"/>
    <child link="A9_link"/>
    <origin xyz="0 -0.075 0.07" rpy="0 0 0"/>
    <axis xyz="0 1 0" rpy="0.0 0.0 0.0"/>
    <limit velocity="12" effort="200" lower="-3.1415" upper="3.1415"/>
  </joint>
  <link name="A10_link">
    <inertial>
      <inertia ixz="0.0" ixx="0.013675" ixy="0.0" izz="0.00735" iyy="0.013675" iyz="0.0"/>
      <mass value="3"/>
      <origin xyz="0.0 0.0 0.1" rpy="0.0 0.0 0.0"/>
    </inertial>
    <visual>
      <geometry>
        <cylinder length="0.2" radius="0.07"/>
      </geometry>
      <material name="blue">
        <color rgba="0.0 0.0 1.0 1.0"/>
      </material>
      <origin xyz="0.0 0.0 0.1" rpy="0.0 0.0 0.0"/>
    </visual>
    <collision>
      <geometry>
        <cylinder length="0.2" radius="0.07"/>
      </geometry>
      <origin xyz="0.0 0.0 0.1" rpy="0.0 0.0 0.0"/>
    </collision>
  </link>
  <joint type="revolute" name="A10_joint">
    <parent link="A9_link"/>
    <child link="A10_link"/>
    <origin xyz="0 -0.075 0.07" rpy="0 0 0"/>
    <axis xyz="0 0 1" rpy="0.0 0.0 0.0"/>
    <limit velocity="12" effort="200" lower="-6.283" upper="6.283"/>
  </joint>
  <link name="EEA_link">
    <inertial>
      <inertia ixz="0.0" ixx="0.00333333333333" ixy="0.0" izz="0.00333333333333" iyy="0.00333333333333" iyz="0.0"/>
      <mass value="2.0"/>
      <origin xyz="0.0 0.0 0.05" rpy="0 0 0"/>
    </inertial>
    <visual>
      <geometry>
        <box size="0.1 0.1 0.1"/>
      </geometry>
      <material name="blue">
        <color rgba="0.0 0.0 1.0 1.0"/>
      </material>
      <origin xyz="0.0 0.0 0.05" rpy="0 0 0"/>
    </visual>
    <collision>
      <geometry>
        <box size="0.1 0.1 0.1"/>
      </geometry>
      <origin xyz="0.0 0.0 0.05" rpy="0 0 0"/>
    </collision>
  </link>
  <joint type="fixed" name="EEA_joint">
    <parent link="A10_link"/>
    <child link="EEA_link"/>
    <origin xyz="0 0 0.2" rpy="0 0 0"/>
  </joint>
  <link name="A_TCP_link"/>
  <joint type="fixed" name="A_TCP_joint">
    <parent link="EEA_link"/>
    <child link="A_TCP_link"/>
    <origin xyz="0.0 0.0 0.1" rpy="0 0 0"/>
  </joint>
  <joint type="fixed" name="B1_base_connection">
    <parent link="base_link"/>
    <child link="B1_base"/>
    <origin xyz="0.0 0.3464 0.0" rpy="3.14159265359 0.0 0.0"/>
  </joint>
  <link name="B1_base"/>
  <link name="B1_link">
    <inertial>
      <inertia ixz="0.0" ixx="0.043675" ixy="0.0" izz="0.00735" iyy="0.043675" iyz="0.0"/>
      <mass value="3.0"/>
      <origin xyz="0.0 0.0 0.2" rpy="0.0 0.0 0.0"/>
    </inertial>
    <visual>
      <geometry>
        <cylinder length="0.4" radius="0.07"/>
      </geometry>
      <material name="blue">
        <color rgba="0.0 0.0 1.0 1.0"/>
      </material>
      <origin xyz="0.0 0.0 0.2" rpy="0.0 0.0 0.0"/>
    </visual>
    <collision>
      <geometry>
        <cylinder length="0.4" radius="0.07"/>
      </geometry>
      <origin xyz="0.0 0.0 0.2" rpy="0.0 0.0 0.0"/>
    </collision>
  </link>
  <joint type="revolute" name="B1_joint">
    <parent link="B1_base"/>
    <child link="B1_link"/>
    <origin xyz="0 0 0" rpy="0 0 0"/>
    <axis xyz="0 0 1" rpy="0.0 0.0 0.0"/>
    <limit velocity="12" effort="200" lower="-6.283" upper="6.283"/>
  </joint>
  <link name="B2_link">
    <inertial>
      <inertia ixz="0.0" ixx="0.0049" ixy="0.0" izz="0.0049" iyy="0.0049" iyz="0.0"/>
      <mass value="1.5"/>
      <origin xyz="0 0 0.07" rpy="0 0 0"/>
    </inertial>
    <visual>
      <geometry>
        <mesh filename="package://esa_mirror/model_resources/meshes/simple/esa_elbow_base.stl" scale="0.001 0.001 0.001"/>
      </geometry>
      <material name="custom"/>
      <origin xyz="0 0 0" rpy="0 0 0"/>
    </visual>
    <collision>
      <geometry>
        <mesh filename="package://esa_mirror/model_resources/meshes/simple/esa_elbow_base.stl" scale="0.001 0.001 0.001"/>
      </geometry>
      <origin xyz="0 0 0" rpy="0 0 0"/>
    </collision>
  </link>
  <joint type="fixed" name="B2_joint">
    <parent link="B1_link"/>
    <child link="B2_link"/>
    <origin xyz="0 0 0.4" rpy="0 0 0"/>
  </joint>
  <link name="B3_link">
    <inertial>
      <inertia ixz="0.0" ixx="0.0049" ixy="0.0" izz="0.0049" iyy="0.0049" iyz="0.0"/>
      <mass value="1.5"/>
      <origin xyz="0 -0.075 0" rpy="0 0 0"/>
    </inertial>
    <visual>
      <geometry>
        <mesh filename="package://esa_mirror/model_resources/meshes/simple/esa_elbow_link.stl" scale="0.001 0.001 0.001"/>
      </geometry>
      <material name="custom"/>
      <origin xyz="0 0 0" rpy="0 0 0"/>
    </visual>
    <collision>
      <geometry>
        <mesh filename="package://esa_mirror/model_resources/meshes/simple/esa_elbow_link.stl" scale="0.001 0.001 0.001"/>
      </geometry>
      <origin xyz="0 0 0" rpy="0 0 0"/>
    </collision>
  </link>
  <joint type="revolute" name="B3_joint">
    <parent link="B2_link"/>
    <child link="B3_link"/>
    <origin xyz="0 -0.075 0.07" rpy="0 0 0"/>
    <axis xyz="0 1 0" rpy="0.0 0.0 0.0"/>
    <limit velocity="12" effort="200" lower="-3.1415" upper="3.1415"/>
  </joint>
  <link name="B4_link">
    <inertial>
      <inertia ixz="0.0" ixx="0.043675" ixy="0.0" izz="0.00735" iyy="0.043675" iyz="0.0"/>
      <mass value="3.0"/>
      <origin xyz="0.0 0.0 0.2" rpy="0.0 0.0 0.0"/>
    </inertial>
    <visual>
      <geometry>
        <cylinder length="0.4" radius="0.07"/>
      </geometry>
      <material name="blue">
        <color rgba="0.0 0.0 1.0 1.0"/>
      </material>
      <origin xyz="0.0 0.0 0.2" rpy="0.0 0.0 0.0"/>
    </visual>
    <collision>
      <geometry>
        <cylinder length="0.4" radius="0.07"/>
      </geometry>
      <origin xyz="0.0 0.0 0.2" rpy="0.0 0.0 0.0"/>
    </collision>
  </link>
  <joint type="fixed" name="B4_joint">
    <parent link="B3_link"/>
    <child link="B4_link"/>
    <origin xyz="0 -0.075 0.07" rpy="0 0 0"/>
  </joint>
  <link name="B5_link">
    <inertial>
      <inertia ixz="0.0" ixx="0.0049" ixy="0.0" izz="0.0049" iyy="0.0049" iyz="0.0"/>
      <mass value="1.5"/>
      <origin xyz="0 0 0.07" rpy="0 0 0"/>
    </inertial>
    <visual>
      <geometry>
        <mesh filename="package://esa_mirror/model_resources/meshes/simple/esa_elbow_base.stl" scale="0.001 0.001 0.001"/>
      </geometry>
      <material name="custom"/>
      <origin xyz="0 0 0" rpy="0 0 0"/>
    </visual>
    <collision>
      <geometry>
        <mesh filename="package://esa_mirror/model_resources/meshes/simple/esa_elbow_base.stl" scale="0.001 0.001 0.001"/>
      </geometry>
      <origin xyz="0 0 0" rpy="0 0 0"/>
    </collision>
  </link>
  <joint type="fixed" name="B5_joint">
    <parent link="B4_link"/>
    <child link="B5_link"/>
    <origin xyz="0 0 0.4" rpy="0 0 3.14159265359"/>
  </joint>
  <link name="B6_link">
    <inertial>
      <inertia ixz="0.0" ixx="0.0049" ixy="0.0" izz="0.0049" iyy="0.0049" iyz="0.0"/>
      <mass value="1.5"/>
      <origin xyz="0 -0.075 0" rpy="0 0 0"/>
    </inertial>
    <visual>
      <geometry>
        <mesh filename="package://esa_mirror/model_resources/meshes/simple/esa_elbow_link.stl" scale="0.001 0.001 0.001"/>
      </geometry>
      <material name="custom"/>
      <origin xyz="0 0 0" rpy="0 0 0"/>
    </visual>
    <collision>
      <geometry>
        <mesh filename="package://esa_mirror/model_resources/meshes/simple/esa_elbow_link.stl" scale="0.001 0.001 0.001"/>
      </geometry>
      <origin xyz="0 0 0" rpy="0 0 0"/>
    </collision>
  </link>
  <joint type="revolute" name="B6_joint">
    <parent link="B5_link"/>
    <child link="B6_link"/>
    <origin xyz="0 -0.075 0.07" rpy="0 0 0"/>
    <axis xyz="0 1 0" rpy="0.0 0.0 0.0"/>
    <limit velocity="12" effort="200" lower="-3.1415" upper="3.1415"/>
  </joint>
  <link name="B7_link">
    <inertial>
      <inertia ixz="0.0" ixx="0.043675" ixy="0.0" izz="0.00735" iyy="0.043675" iyz="0.0"/>
      <mass value="3.0"/>
      <origin xyz="0.0 0.0 0.2" rpy="0.0 0.0 0.0"/>
    </inertial>
    <visual>
      <geometry>
        <cylinder length="0.4" radius="0.07"/>
      </geometry>
      <material name="blue">
        <color rgba="0.0 0.0 1.0 1.0"/>
      </material>
      <origin xyz="0.0 0.0 0.2" rpy="0.0 0.0 0.0"/>
    </visual>
    <collision>
      <geometry>
        <cylinder length="0.4" radius="0.07"/>
      </geometry>
      <origin xyz="0.0 0.0 0.2" rpy="0.0 0.0 0.0"/>
    </collision>
  </link>
  <joint type="revolute" name="B7_joint">
    <parent link="B6_link"/>
    <child link="B7_link"/>
    <origin xyz="0 -0.075 0.07" rpy="0 0 0"/>
    <axis xyz="0 0 1" rpy="0.0 0.0 0.0"/>
    <limit velocity="12" effort="200" lower="-6.283" upper="6.283"/>
  </joint>
  <link name="B8_link">
    <inertial>
      <inertia ixz="0.0" ixx="0.0049" ixy="0.0" izz="0.0049" iyy="0.0049" iyz="0.0"/>
      <mass value="1.5"/>
      <origin xyz="0 0 0.07" rpy="0 0 0"/>
    </inertial>
    <visual>
      <geometry>
        <mesh filename="package://esa_mirror/model_resources/meshes/simple/esa_elbow_base.stl" scale="0.001 0.001 0.001"/>
      </geometry>
      <material name="custom"/>
      <origin xyz="0 0 0" rpy="0 0 0"/>
    </visual>
    <collision>
      <geometry>
        <mesh filename="package://esa_mirror/model_resources/meshes/simple/esa_elbow_base.stl" scale="0.001 0.001 0.001"/>
      </geometry>
      <origin xyz="0 0 0" rpy="0 0 0"/>
    </collision>
  </link>
  <joint type="fixed" name="B8_joint">
    <parent link="B7_link"/>
    <child link="B8_link"/>
    <origin xyz="0 0 0.4" rpy="0 0 0"/>
  </joint>
  <link name="B9_link">
    <inertial>
      <inertia ixz="0.0" ixx="0.0049" ixy="0.0" izz="0.0049" iyy="0.0049" iyz="0.0"/>
      <mass value="1.5"/>
      <origin xyz="0 -0.075 0" rpy="0 0 0"/>
    </inertial>
    <visual>
      <geometry>
        <mesh filename="package://esa_mirror/model_resources/meshes/simple/esa_elbow_link.stl" scale="0.001 0.001 0.001"/>
      </geometry>
      <material name="custom"/>
      <origin xyz="0 0 0" rpy="0 0 0"/>
    </visual>
    <collision>
      <geometry>
        <mesh filename="package://esa_mirror/model_resources/meshes/simple/esa_elbow_link.stl" scale="0.001 0.001 0.001"/>
      </geometry>
      <origin xyz="0 0 0" rpy="0 0 0"/>
    </collision>
  </link>
  <joint type="revolute" name="B9_joint">
    <parent link="B8_link"/>
    <child link="B9_link"/>
    <origin xyz="0 -0.075 0.07" rpy="0 0 0"/>
    <axis xyz="0 1 0" rpy="0.0 0.0 0.0"/>
    <limit velocity="12" effort="200" lower="-3.1415" upper="3.1415"/>
  </joint>
  <link name="B10_link">
    <inertial>
      <inertia ixz="0.0" ixx="0.013675" ixy="0.0" izz="0.00735" iyy="0.013675" iyz="0.0"/>
      <mass value="3"/>
      <origin xyz="0.0 0.0 0.1" rpy="0.0 0.0 0.0"/>
    </inertial>
    <visual>
      <geometry>
        <cylinder length="0.2" radius="0.07"/>
      </geometry>
      <material name="blue">
        <color rgba="0.0 0.0 1.0 1.0"/>
      </material>
      <origin xyz="0.0 0.0 0.1" rpy="0.0 0.0 0.0"/>
    </visual>
    <collision>
      <geometry>
        <cylinder length="0.2" radius="0.07"/>
      </geometry>
      <origin xyz="0.0 0.0 0.1" rpy="0.0 0.0 0.0"/>
    </collision>
  </link>
  <joint type="revolute" name="B10_joint">
    <parent link="B9_link"/>
    <child link="B10_link"/>
    <origin xyz="0 -0.075 0.07" rpy="0 0 0"/>
    <axis xyz="0 0 1" rpy="0.0 0.0 0.0"/>
    <limit velocity="12" effort="200" lower="-6.283" upper="6.283"/>
  </joint>
  <link name="EEB_link">
    <inertial>
      <inertia ixz="0.0" ixx="0.00333333333333" ixy="0.0" izz="0.00333333333333" iyy="0.00333333333333" iyz="0.0"/>
      <mass value="2.0"/>
      <origin xyz="0.0 0.0 0.05" rpy="0 0 0"/>
    </inertial>
    <visual>
      <geometry>
        <box size="0.1 0.1 0.1"/>
      </geometry>
      <material name="blue">
        <color rgba="0.0 0.0 1.0 1.0"/>
      </material>
      <origin xyz="0.0 0.0 0.05" rpy="0 0 0"/>
    </visual>
    <collision>
      <geometry>
        <box size="0.1 0.1 0.1"/>
      </geometry>
      <origin xyz="0.0 0.0 0.05" rpy="0 0 0"/>
    </collision>
  </link>
  <joint type="fixed" name="EEB_joint">
    <parent link="B10_link"/>
    <child link="EEB_link"/>
    <origin xyz="0 0 0.2" rpy="0 0 0"/>
  </joint>
  <link name="B_TCP_link"/>
  <joint type="fixed" name="B_TCP_joint">
    <parent link="EEB_link"/>
    <child link="B_TCP_link"/>
    <origin xyz="0.0 0.0 0.1" rpy="0 0 0"/>
  </joint>
  <joint type="fixed" name="C1_base_connection">
    <parent link="base_link"/>
    <child link="C1_base"/>
    <origin xyz="-0.2999824 -0.1732 0.0" rpy="3.14159265359 0.0 0.0"/>
  </joint>
  <link name="C1_base"/>
  <link name="C1_link">
    <inertial>
      <inertia ixz="0.0" ixx="0.043675" ixy="0.0" izz="0.00735" iyy="0.043675" iyz="0.0"/>
      <mass value="3.0"/>
      <origin xyz="0.0 0.0 0.2" rpy="0.0 0.0 0.0"/>
    </inertial>
    <visual>
      <geometry>
        <cylinder length="0.4" radius="0.07"/>
      </geometry>
      <material name="blue">
        <color rgba="0.0 0.0 1.0 1.0"/>
      </material>
      <origin xyz="0.0 0.0 0.2" rpy="0.0 0.0 0.0"/>
    </visual>
    <collision>
      <geometry>
        <cylinder length="0.4" radius="0.07"/>
      </geometry>
      <origin xyz="0.0 0.0 0.2" rpy="0.0 0.0 0.0"/>
    </collision>
  </link>
  <joint type="revolute" name="C1_joint">
    <parent link="C1_base"/>
    <child link="C1_link"/>
    <origin xyz="0 0 0" rpy="0 0 0"/>
    <axis xyz="0 0 1" rpy="0.0 0.0 0.0"/>
    <limit velocity="12" effort="200" lower="-6.283" upper="6.283"/>
  </joint>
  <link name="C2_link">
    <inertial>
      <inertia ixz="0.0" ixx="0.0049" ixy="0.0" izz="0.0049" iyy="0.0049" iyz="0.0"/>
      <mass value="1.5"/>
      <origin xyz="0 0 0.07" rpy="0 0 0"/>
    </inertial>
    <visual>
      <geometry>
        <mesh filename="package://esa_mirror/model_resources/meshes/simple/esa_elbow_base.stl" scale="0.001 0.001 0.001"/>
      </geometry>
      <material name="custom"/>
      <origin xyz="0 0 0" rpy="0 0 0"/>
    </visual>
    <collision>
      <geometry>
        <mesh filename="package://esa_mirror/model_resources/meshes/simple/esa_elbow_base.stl" scale="0.001 0.001 0.001"/>
      </geometry>
      <origin xyz="0 0 0" rpy="0 0 0"/>
    </collision>
  </link>
  <joint type="fixed" name="C2_joint">
    <parent link="C1_link"/>
    <child link="C2_link"/>
    <origin xyz="0 0 0.4" rpy="0 0 0"/>
  </joint>
  <link name="C3_link">
    <inertial>
      <inertia ixz="0.0" ixx="0.0049" ixy="0.0" izz="0.0049" iyy="0.0049" iyz="0.0"/>
      <mass value="1.5"/>
      <origin xyz="0 -0.075 0" rpy="0 0 0"/>
    </inertial>
    <visual>
      <geometry>
        <mesh filename="package://esa_mirror/model_resources/meshes/simple/esa_elbow_link.stl" scale="0.001 0.001 0.001"/>
      </geometry>
      <material name="custom"/>
      <origin xyz="0 0 0" rpy="0 0 0"/>
    </visual>
    <collision>
      <geometry>
        <mesh filename="package://esa_mirror/model_resources/meshes/simple/esa_elbow_link.stl" scale="0.001 0.001 0.001"/>
      </geometry>
      <origin xyz="0 0 0" rpy="0 0 0"/>
    </collision>
  </link>
  <joint type="revolute" name="C3_joint">
    <parent link="C2_link"/>
    <child link="C3_link"/>
    <origin xyz="0 -0.075 0.07" rpy="0 0 0"/>
    <axis xyz="0 1 0" rpy="0.0 0.0 0.0"/>
    <limit velocity="12" effort="200" lower="-3.1415" upper="3.1415"/>
  </joint>
  <link name="C4_link">
    <inertial>
      <inertia ixz="0.0" ixx="0.043675" ixy="0.0" izz="0.00735" iyy="0.043675" iyz="0.0"/>
      <mass value="3.0"/>
      <origin xyz="0.0 0.0 0.2" rpy="0.0 0.0 0.0"/>
    </inertial>
    <visual>
      <geometry>
        <cylinder length="0.4" radius="0.07"/>
      </geometry>
      <material name="blue">
        <color rgba="0.0 0.0 1.0 1.0"/>
      </material>
      <origin xyz="0.0 0.0 0.2" rpy="0.0 0.0 0.0"/>
    </visual>
    <collision>
      <geometry>
        <cylinder length="0.4" radius="0.07"/>
      </geometry>
      <origin xyz="0.0 0.0 0.2" rpy="0.0 0.0 0.0"/>
    </collision>
  </link>
  <joint type="fixed" name="C4_joint">
    <parent link="C3_link"/>
    <child link="C4_link"/>
    <origin xyz="0 -0.075 0.07" rpy="0 0 0"/>
  </joint>
  <link name="C5_link">
    <inertial>
      <inertia ixz="0.0" ixx="0.0049" ixy="0.0" izz="0.0049" iyy="0.0049" iyz="0.0"/>
      <mass value="1.5"/>
      <origin xyz="0 0 0.07" rpy="0 0 0"/>
    </inertial>
    <visual>
      <geometry>
        <mesh filename="package://esa_mirror/model_resources/meshes/simple/esa_elbow_base.stl" scale="0.001 0.001 0.001"/>
      </geometry>
      <material name="custom"/>
      <origin xyz="0 0 0" rpy="0 0 0"/>
    </visual>
    <collision>
      <geometry>
        <mesh filename="package://esa_mirror/model_resources/meshes/simple/esa_elbow_base.stl" scale="0.001 0.001 0.001"/>
      </geometry>
      <origin xyz="0 0 0" rpy="0 0 0"/>
    </collision>
  </link>
  <joint type="fixed" name="C5_joint">
    <parent link="C4_link"/>
    <child link="C5_link"/>
    <origin xyz="0 0 0.4" rpy="0 0 3.14159265359"/>
  </joint>
  <link name="C6_link">
    <inertial>
      <inertia ixz="0.0" ixx="0.0049" ixy="0.0" izz="0.0049" iyy="0.0049" iyz="0.0"/>
      <mass value="1.5"/>
      <origin xyz="0 -0.075 0" rpy="0 0 0"/>
    </inertial>
    <visual>
      <geometry>
        <mesh filename="package://esa_mirror/model_resources/meshes/simple/esa_elbow_link.stl" scale="0.001 0.001 0.001"/>
      </geometry>
      <material name="custom"/>
      <origin xyz="0 0 0" rpy="0 0 0"/>
    </visual>
    <collision>
      <geometry>
        <mesh filename="package://esa_mirror/model_resources/meshes/simple/esa_elbow_link.stl" scale="0.001 0.001 0.001"/>
      </geometry>
      <origin xyz="0 0 0" rpy="0 0 0"/>
    </collision>
  </link>
  <joint type="revolute" name="C6_joint">
    <parent link="C5_link"/>
    <child link="C6_link"/>
    <origin xyz="0 -0.075 0.07" rpy="0 0 0"/>
    <axis xyz="0 1 0" rpy="0.0 0.0 0.0"/>
    <limit velocity="12" effort="200" lower="-3.1415" upper="3.1415"/>
  </joint>
  <link name="C7_link">
    <inertial>
      <inertia ixz="0.0" ixx="0.043675" ixy="0.0" izz="0.00735" iyy="0.043675" iyz="0.0"/>
      <mass value="3.0"/>
      <origin xyz="0.0 0.0 0.2" rpy="0.0 0.0 0.0"/>
    </inertial>
    <visual>
      <geometry>
        <cylinder length="0.4" radius="0.07"/>
      </geometry>
      <material name="blue">
        <color rgba="0.0 0.0 1.0 1.0"/>
      </material>
      <origin xyz="0.0 0.0 0.2" rpy="0.0 0.0 0.0"/>
    </visual>
    <collision>
      <geometry>
        <cylinder length="0.4" radius="0.07"/>
      </geometry>
      <origin xyz="0.0 0.0 0.2" rpy="0.0 0.0 0.0"/>
    </collision>
  </link>
  <joint type="revolute" name="C7_joint">
    <parent link="C6_link"/>
    <child link="C7_link"/>
    <origin xyz="0 -0.075 0.07" rpy="0 0 0"/>
    <axis xyz="0 0 1" rpy="0.0 0.0 0.0"/>
    <limit velocity="12" effort="200" lower="-6.283" upper="6.283"/>
  </joint>
  <link name="C8_link">
    <inertial>
      <inertia ixz="0.0" ixx="0.0049" ixy="0.0" izz="0.0049" iyy="0.0049" iyz="0.0"/>
      <mass value="1.5"/>
      <origin xyz="0 0 0.07" rpy="0 0 0"/>
    </inertial>
    <visual>
      <geometry>
        <mesh filename="package://esa_mirror/model_resources/meshes/simple/esa_elbow_base.stl" scale="0.001 0.001 0.001"/>
      </geometry>
      <material name="custom"/>
      <origin xyz="0 0 0" rpy="0 0 0"/>
    </visual>
    <collision>
      <geometry>
        <mesh filename="package://esa_mirror/model_resources/meshes/simple/esa_elbow_base.stl" scale="0.001 0.001 0.001"/>
      </geometry>
      <origin xyz="0 0 0" rpy="0 0 0"/>
    </collision>
  </link>
  <joint type="fixed" name="C8_joint">
    <parent link="C7_link"/>
    <child link="C8_link"/>
    <origin xyz="0 0 0.4" rpy="0 0 0"/>
  </joint>
  <link name="C9_link">
    <inertial>
      <inertia ixz="0.0" ixx="0.0049" ixy="0.0" izz="0.0049" iyy="0.0049" iyz="0.0"/>
      <mass value="1.5"/>
      <origin xyz="0 -0.075 0" rpy="0 0 0"/>
    </inertial>
    <visual>
      <geometry>
        <mesh filename="package://esa_mirror/model_resources/meshes/simple/esa_elbow_link.stl" scale="0.001 0.001 0.001"/>
      </geometry>
      <material name="custom"/>
      <origin xyz="0 0 0" rpy="0 0 0"/>
    </visual>
    <collision>
      <geometry>
        <mesh filename="package://esa_mirror/model_resources/meshes/simple/esa_elbow_link.stl" scale="0.001 0.001 0.001"/>
      </geometry>
      <origin xyz="0 0 0" rpy="0 0 0"/>
    </collision>
  </link>
  <joint type="revolute" name="C9_joint">
    <parent link="C8_link"/>
    <child link="C9_link"/>
    <origin xyz="0 -0.075 0.07" rpy="0 0 0"/>
    <axis xyz="0 1 0" rpy="0.0 0.0 0.0"/>
    <limit velocity="12" effort="200" lower="-3.1415" upper="3.1415"/>
  </joint>
  <link name="C10_link">
    <inertial>
      <inertia ixz="0.0" ixx="0.013675" ixy="0.0" izz="0.00735" iyy="0.013675" iyz="0.0"/>
      <mass value="3"/>
      <origin xyz="0.0 0.0 0.1" rpy="0.0 0.0 0.0"/>
    </inertial>
    <visual>
      <geometry>
        <cylinder length="0.2" radius="0.07"/>
      </geometry>
      <material name="blue">
        <color rgba="0.0 0.0 1.0 1.0"/>
      </material>
      <origin xyz="0.0 0.0 0.1" rpy="0.0 0.0 0.0"/>
    </visual>
    <collision>
      <geometry>
        <cylinder length="0.2" radius="0.07"/>
      </geometry>
      <origin xyz="0.0 0.0 0.1" rpy="0.0 0.0 0.0"/>
    </collision>
  </link>
  <joint type="revolute" name="C10_joint">
    <parent link="C9_link"/>
    <child link="C10_link"/>
    <origin xyz="0 -0.075 0.07" rpy="0 0 0"/>
    <axis xyz="0 0 1" rpy="0.0 0.0 0.0"/>
    <limit velocity="12" effort="200" lower="-6.283" upper="6.283"/>
  </joint>
  <link name="EEC_link">
    <inertial>
      <inertia ixz="0.0" ixx="0.00333333333333" ixy="0.0" izz="0.00333333333333" iyy="0.00333333333333" iyz="0.0"/>
      <mass value="2.0"/>
      <origin xyz="0.0 0.0 0.05" rpy="0 0 0"/>
    </inertial>
    <visual>
      <geometry>
        <box size="0.1 0.1 0.1"/>
      </geometry>
      <material name="blue">
        <color rgba="0.0 0.0 1.0 1.0"/>
      </material>
      <origin xyz="0.0 0.0 0.05" rpy="0 0 0"/>
    </visual>
    <collision>
      <geometry>
        <box size="0.1 0.1 0.1"/>
      </geometry>
      <origin xyz="0.0 0.0 0.05" rpy="0 0 0"/>
    </collision>
  </link>
  <joint type="fixed" name="EEC_joint">
    <parent link="C10_link"/>
    <child link="EEC_link"/>
    <origin xyz="0 0 0.2" rpy="0 0 0"/>
  </joint>
  <link name="C_TCP_link"/>
  <joint type="fixed" name="C_TCP_joint">
    <parent link="EEC_link"/>
    <child link="C_TCP_link"/>
    <origin xyz="0.0 0.0 0.1" rpy="0 0 0"/>
  </joint>
</robot>
